Workbook
Name SegmentaciónDeDatos_Tamaño: #N/A
Name SegmentaciónDeDatos_Tiene_Anexo_2: #N/A

Sheet Detalle1
A1: Detalles para Cuenta de Nombre del requerimiento - Gerencia: Banca Digital, Mes_Cronograma: 2027 - 3, Estado Evaluación de Iniciativas: Pendiente de Atención
A3: Nombre del requerimiento | B3: Prioridad | C3: Orden de Atención | D3: Esfuerzo Estimado Desarrollo | E3: Tamaño | F3: Gerencia | G3: Subgerencia | H3: Sección | I3: Memorando 2026 | J3: Tiene Anexo 2 | K3: Categoría | L3: Estado Evaluación de Iniciativas | M3: Seccion TI | N3: Responsable de atención | O3: Gestor | P3: Comentario | Q3: Comienzo Desarrollo | R3: Fin Desarrollo | S3: Comienzo Calidad | T3: Fin Calidad | U3: Comienzo Producción | V3: Fin Producción | W3: Días Calendario | X3: Hay Fecha Inicio | Y3: Tiene esfuerzo | Z3: Indicador Fechas | AA3: Mes_Cronograma
A4: Adecuación del no cobro de comisión por reposición de Tarjeta de Débito por bloqueos de fraude | B4: 1 | C4: 14 | D4: 3 meses | E4: Mediano | F4: Banca Digital | G4: Canales Alternos | H4: Canales Virtuales | I4: MEMORANDO N° 00000091 - 2026-BN/3252 | J4: Sí | K4: Recomendación | L4: Pendiente de Atención | M4: Sistemas Bancarios | N4: Norma Fukunaga | O4: Omar Sarmiento | Q4: 46301 | R4: 46400 | S4: 46407 | T4: 46463 | U4: 46470 | V4: 46479 | W4: 178 | X4: Con Fecha | Y4: Con esfuerzo | Z4: 🟢 A tiempo | AA4: 2027 - 3
A5: Visa Mandatorio - Autorizaciones parciales para las transacciones AFT | B5: 1 | C5: 2 | D5: 4 meses | E5: Grande | F5: Banca Digital | G5: Canales Alternos | H5: Canales Virtuales | I5: MEMORANDO N° 00000091 -2026-BN/3252 | J5: Sí | K5: Mandatorio | L5: Pendiente de Atención | M5: Sistemas Bancarios | N5: Vladimir Cajavilca | O5: Omar Sarmiento | Q5: 46204 | R5: 46367 | S5: 46374 | T5: 46448 | U5: 46455 | V5: 46469 | W5: 265 | X5: Con Fecha | Y5: Con esfuerzo | Z5: 🟢 A tiempo | AA5: 2027 - 3
A6: Solicitud de Notificaciones | B6: 1 | C6: Por definir | D6: 4 meses | E6: Grande | F6: Banca Digital | G6: Canales Alternos | H6: Canales Virtuales | I6: MEMORANDO N° 00000518 - 2025-BN/3252 | J6: Sí | K6: Evolutivo | L6: Pendiente de Atención | M6: Soluciones Digitales | N6: Mario Carbajo | O6: Omar Sarmiento | Q6: 46204 | R6: 46367 | S6: 46374 | T6: 46448 | U6: 46455 | V6: 46469 | W6: 265 | X6: Con Fecha | Y6: Con esfuerzo | Z6: 🟢 A tiempo | AA6: 2027 - 3

Sheet ResumenTemporal
A3: Tabla 1 - Requerimientos que cuentan con anexo 2 por gerencias | B3: Tiene Anexo 2 ¿? | G3: Tabla 3 - Categorias de los requerimientos por gerencias | H3: Categoría
A4: Gerencia | B4: No | C4: Sí | D4: Total general | G4: Gerencia | H4: Correctivo | I4: Evolutivo | J4: Normativo | K4: Recomendación | L4: (en blanco) | M4: Mandatorio | N4: Total general
A5: Banca Digital | B5: 1 | C5: 50 | D5: 51 | G5: Banca Digital | H5: 5 | I5: 13 | J5: 7 | K5: 9 | L5: 1 | M5: 16 | N5: 51
A6: Finanzas y Tesorería | C6: 6 | D6: 6 | G6: Finanzas y Tesorería | I6: 1 | J6: 5 | N6: 6
A7: Operaciones | C7: 42 | D7: 42 | G7: Operaciones | H7: 2 | I7: 15 | J7: 1 | K7: 24 | N7: 42
A8: OPLAFT | C8: 2 | D8: 2 | G8: OPLAFT | I8: 2 | N8: 2
A9: Productos e Inclusión Financiera | C9: 16 | D9: 16 | G9: Productos e Inclusión Financiera | H9: 1 | I9: 5 | J9: 4 | K9: 6 | N9: 16
A10: Red de Agencias | C10: 2 | D10: 2 | G10: Red de Agencias | I10: 1 | J10: 1 | N10: 2
A11: Riesgos | C11: 6 | D11: 6 | G11: Riesgos | J11: 3 | K11: 3 | N11: 6
A12: Innovación y Transformación Digital | C12: 1 | D12: 1 | G12: Innovación y Transformación Digital | J12: 1 | N12: 1
A13: Administración y Logistica | C13: 2 | D13: 2 | G13: Administración y Logistica | I13: 1 | J13: 1 | N13: 2
A14: Total general | B14: 1 | C14: 127 | D14: 128 | G14: Total general | H14: 8 | I14: 38 | J14: 23 | K14: 42 | L14: 1 | M14: 16 | N14: 128
A26: Tabla 4 - Requerimientos según su tamaño y gerencia | B26: Tamaño
A27: Gerencia | B27: Grande | C27: Mediano | D27: Pequeño | E27: No definido | F27: Extra Grande | G27: Proyecto | H27: Total general
A28: Banca Digital | B28: 11 | C28: 29 | D28: 7 | E28: 4 | H28: 51
A29: Finanzas y Tesorería | B29: 1 | C29: 4 | D29: 1 | H29: 6
A30: Operaciones | B30: 8 | C30: 18 | D30: 3 | E30: 6 | F30: 7 | H30: 42
A31: OPLAFT | C31: 1 | D31: 1 | H31: 2
A32: Productos e Inclusión Financiera | C32: 11 | D32: 2 | F32: 3 | H32: 16
A33: Red de Agencias | C33: 1 | G33: 1 | H33: 2
A34: Riesgos | B34: 1 | C34: 2 | E34: 2 | G34: 1 | H34: 6
A35: Innovación y Transformación Digital | C35: 1 | H35: 1
A36: Administración y Logistica | C36: 1 | F36: 1 | H36: 2
A37: Total general | B37: 21 | C37: 68 | D37: 14 | E37: 12 | F37: 11 | G37: 2 | H37: 128
A44: Gerencia | B44: Tabla 5 - Requerimientos según su estado y gerencia
A45: Banca Digital | B45: 51
A46: Finanzas y Tesorería | B46: 6
A47: Operaciones | B47: 42
A48: OPLAFT | B48: 2
A49: Productos e Inclusión Financiera | B49: 16
A50: Red de Agencias | B50: 2
A51: Riesgos | B51: 6
A52: Innovación y Transformación Digital | B52: 1
A53: Administración y Logistica | B53: 2
A54: Total general | B54: 128
A61: Tabla 1 - Requerimientos que cuentan con anexo 2 por gerencias | B61: Tiene Anexo 2 ¿? | C61: Estado Evaluación de Iniciativas
B62: No | C62: Sí | G62: Total general
A63: Gerencia | B63: Observado | C63: Observado | D63: Pendiente de Atención | E63: Por evaluar | F63: Descartado
A64: Banca Digital | B64: 1 | D64: 46 | E64: 4 | G64: 51
A65: Operaciones | C65: 2 | D65: 36 | E65: 2 | F65: 2 | G65: 42
...

Sheet PRIORIDAD UNO
Q1: Leyenda - Comienzo Desarrollo | T1: Leyenda - Fechas
A2: =_xlfn.CONCAT("Total = ",COUNTA(PRIORIDAD_UNO[Nombre del requerimiento])) -> Total = 128 | Q2: 🟠: Tamaño no definido. | S2: ⚠️Error: No está registrado en hoja "Cálculos Manual".
Q3: 🟣: Iniciativa es un proyecto.
A4: Nombre del requerimiento | B4: Prioridad | C4: Orden de Atención | D4: Esfuerzo Estimado Desarrollo | E4: Tamaño | F4: Gerencia | G4: Subgerencia | H4: Sección | I4: Memorando 2026 | J4: Tiene Anexo 2 | K4: Categoría | L4: Estado Evaluación de Iniciativas | M4: Seccion TI | N4: Responsable de atención | O4: Gestor | P4: Comentario | Q4: Comienzo Desarrollo | R4: Fin Desarrollo | S4: Comienzo Calidad | T4: Fin Calidad | U4: Comienzo Producción | V4: Fin Producción | W4: Días Calendario | X4: Hay Fecha Inicio | Y4: Tiene esfuerzo | Z4: Indicador Fechas | AA4: Mes_Cronograma | AB4: Backlog ID
A5: Vulnerabilidad en la plataforma Pagalo.pe reportada por el equipo de Seguridad Informatica en la descarga de comprobantes de pago | B5: 1 | C5: 4 | D5: 1 mes | E5: =IF(OR(ISBLANK(PRIORIDAD_UNO[[#This Row],[Esfuerzo Estimado Desarrollo]]),PRIORIDAD_UNO[[#This Row],[Esfuerzo Estimado Desarrollo]]="No definido"),"No definido", IF(VALUE(TRIM(LEFT(PRIORIDAD_UNO[[#This Row],[Esfuerzo Estimado Desarrollo]],2)))<=1,"Pequeño", IF(VALUE(TRIM(LEFT(PRIORIDAD_UNO[[#This Row],[Esfuerzo Estimado Desarrollo]],2)))<=3,"Mediano", IF(VALUE(TRIM(LEFT(PRIORIDAD_UNO[[#This Row],[Esfuerzo Estimado Desarrollo]],2)))<=5,"Grande", IF(VALUE(TRIM(LEFT(PRIORIDAD_UNO[[#This Row],[Esfuerzo Estimado Desarrollo]],2)))<=7,"Extra Grande","Proyecto"))))) -> Pequeño | F5: Banca Digital | G5: Canales Alternos | H5: Canales Virtuales | I5: MEMORANDO N° 00000120 - 2026-BN/3252 | J5: Sí | K5: Evolutivo | L5: Por evaluar | M5: Sistemas Bancarios | N5: Eduardo Cárdenas | O5: Omar Sarmiento | R5: =IF(OR(PRIORIDAD_UNO[[#This Row],[Tamaño]]="No definido",ISBLANK(PRIORIDAD_UNO[[#This Row],[Comienzo Desarrollo]])),"",IF(ISBLANK( VLOOKUP(PRIORIDAD_UNO[[#This Row],[Nombre del requerimiento]],'Cálculos Manual'!A:F,6,FALSE)), WORKDAY(PRIORIDAD_UNO[[#This Row],[Comienzo Desarrollo]], IF(PRIORIDAD_UNO[[#This Row],[Tamaño]]="Pequeño",30,IF(PRIORIDAD_UNO[[#This Row],[Tamaño]]="Mediano",66,IF(PRIORIDAD_UNO[[#This Row],[Tamaño]]="Grande",110,IF(PRIORIDAD_UNO[[#This Row],[Tamaño]]="Extra Grande",154,176)))), FERIADOS[Fecha]), VLOOKUP(PRIORIDAD_UNO[[#This Row],[Nombre del requerimiento]],'Cálculos Manual'!A:F,6,FALSE))) | S5: =IF(PRIORIDAD_UNO[[#This Row],[Fin Desarrollo]]="","",IF(ISBLANK(VLOOKUP(PRIORIDAD_UNO[[#This Row],[Nombre del requerimiento]],'Cálculos Manual'!A:H,8,FALSE)),WORKDAY(PRIORIDAD_UNO[[#This Row],[Fin Desarrollo]],5,FERIADOS[Fecha]), VLOOKUP(PRIORIDAD_UNO[[#This Row],[Nombre del requerimiento]],'Cálculos Manual'!A:H,8,FALSE))) | T5: =IF(PRIORIDAD_UNO[[#This Row],[Comienzo Calidad]]="","",IF(ISBLANK(VLOOKUP(PRIORIDAD_UNO[[#This Row],[Nombre del requerimiento]],'Cálculos Manual'!A:J,10,FALSE)), WORKDAY(PRIORIDAD_UNO[[#This Row],[Comienzo Calidad]],IF(PRIORIDAD_UNO[[#This Row],[Tamaño]]="Pequeño",30,IF(PRIORIDAD_UNO[[#This Row],[Tamaño]]="Mediano",40,50)),FERIADOS[Fecha]), VLOOKUP(PRIORIDAD_UNO[[#This Row],[Nombre del requerimiento]],'Cálculos Manual'!A:J,10,FALSE))) | U5: =IF(PRIORIDAD_UNO[[#This Row],[Fin Calidad]]="","",IF(ISBLANK(VLOOKUP(PRIORIDAD_UNO[[#This Row],[Nombre del requerimiento]],'Cálculos Manual'!A:L,12,FALSE)), WORKDAY(PRIORIDAD_UNO[[#This Row],[Fin Calidad]],5,FERIADOS[Fecha]), VLOOKUP(PRIORIDAD_UNO[[#This Row],[Nombre del requerimiento]],'Cálculos Manual'!A:L,12,FALSE))) | V5: =IF(PRIORIDAD_UNO[[#This Row],[Comienzo Producción]]="","",IF(ISBLANK(VLOOKUP(PRIORIDAD_UNO[[#This Row],[Nombre del requerimiento]],'Cálculos Manual'!A:N,14,FALSE)), WORKDAY(PRIORIDAD_UNO[[#This Row],[Comienzo Producción]],IF(PRIORIDAD_UNO[[#This Row],[Tamaño]]="Grande",10,5),FERIADOS[Fecha]), VLOOKUP(PRIORIDAD_UNO[[#This Row],[Nombre del requerimiento]],'Cálculos Manual'!A:N,14,FALSE))) | W5: =IFERROR(PRIORIDAD_UNO[[#This Row],[Fin Producción]]-PRIORIDAD_UNO[[#This Row],[Comienzo Desarrollo]],"") | X5: =IF(ISBLANK(PRIORIDAD_UNO[[#This Row],[Comienzo Desarrollo]]),"Sin Fecha","Con Fecha") -> Sin Fecha | Y5: =IF(PRIORIDAD_UNO[[#This Row],[Esfuerzo Estimado Desarrollo]]="No definido","Sin esfuerzo","Con esfuerzo") -> Con esfuerzo | Z5: =IF(ISBLANK(PRIORIDAD_UNO[[#This Row],[Comienzo Desarrollo]]),"🔵 Sin Fecha", IF(PRIORIDAD_UNO[[#This Row],[Comienzo Desarrollo]]<TODAY(),"🔴 Vencido", IF(PRIORIDAD_UNO[[#This Row],[Comienzo Desarrollo]]=TODAY(),"🟡 Vence hoy", IF((PRIORIDAD_UNO[[#This Row],[Comienzo Desarrollo]]-TODAY())<=5,"🟠 Por vencer", "🟢 A tiempo")))) -> 🔵 Sin Fecha | AA5: =IF(PRIORIDAD_UNO[[#This Row],[Comienzo Producción]]="","Por Definir",_xlfn.CONCAT(YEAR(PRIORIDAD_UNO[[#This Row],[Comienzo Producción]])," - ", MONTH(PRIORIDAD_UNO[[#This Row],[Comienzo Producción]]))) -> Por Definir | AB5: No está
A6: Visa Mandatorio - Autorizaciones parciales para las transacciones AFT | B6: 1 | C6: 2 | D6: 4 meses | E6: =IF(OR(ISBLANK(PRIORIDAD_UNO[[#This Row],[Esfuerzo Estimado Desarrollo]]),PRIORIDAD_UNO[[#This Row],[Esfuerzo Estimado Desarrollo]]="No definido"),"No definido", IF(VALUE(TRIM(LEFT(PRIORIDAD_UNO[[#This Row],[Esfuerzo Estimado Desarrollo]],2)))<=1,"Pequeño", IF(VALUE(TRIM(LEFT(PRIORIDAD_UNO[[#This Row],[Esfuerzo Estimado Desarrollo]],2)))<=3,"Mediano", IF(VALUE(TRIM(LEFT(PRIORIDAD_UNO[[#This Row],[Esfuerzo Estimado Desarrollo]],2)))<=5,"Grande", IF(VALUE(TRIM(LEFT(PRIORIDAD_UNO[[#This Row],[Esfuerzo Estimado Desarrollo]],2)))<=7,"Extra Grande","Proyecto"))))) -> Grande | F6: Banca Digital | G6: Canales Alternos | H6: Canales Virtuales | I6: MEMORANDO N° 00000091 -2026-BN/3252 | J6: Sí | K6: Mandatorio | L6: Pendiente de Atención | M6: Sistemas Bancarios | N6: Vladimir Cajavilca | O6: Omar Sarmiento | Q6: 46204 | R6: =IF(OR(PRIORIDAD_UNO[[#This Row],[Tamaño]]="No definido",ISBLANK(PRIORIDAD_UNO[[#This Row],[Comienzo Desarrollo]])),"",IF(ISBLANK( VLOOKUP(PRIORIDAD_UNO[[#This Row],[Nombre del requerimiento]],'Cálculos Manual'!A:F,6,FALSE)), WORKDAY(PRIORIDAD_UNO[[#This Row],[Comienzo Desarrollo]], IF(PRIORIDAD_UNO[[#This Row],[Tamaño]]="Pequeño",30,IF(PRIORIDAD_UNO[[#This Row],[Tamaño]]="Mediano",66,IF(PRIORIDAD_UNO[[#This Row],[Tamaño]]="Grande",110,IF(PRIORIDAD_UNO[[#This Row],[Tamaño]]="Extra Grande",154,176)))), FERIADOS[Fecha]), VLOOKUP(PRIORIDAD_UNO[[#This Row],[Nombre del requerimiento]],'Cálculos Manual'!A:F,6,FALSE))) -> 46367 | S6: =IF(PRIORIDAD_UNO[[#This Row],[Fin Desarrollo]]="","",IF(ISBLANK(VLOOKUP(PRIORIDAD_UNO[[#This Row],[Nombre del requerimiento]],'Cálculos Manual'!A:H,8,FALSE)),WORKDAY(PRIORIDAD_UNO[[#This Row],[Fin Desarrollo]],5,FERIADOS[Fecha]), VLOOKUP(PRIORIDAD_UNO[[#This Row],[Nombre del requerimiento]],'Cálculos Manual'!A:H,8,FALSE))) -> 46374 | T6: =IF(PRIORIDAD_UNO[[#This Row],[Comienzo Calidad]]="","",IF(ISBLANK(VLOOKUP(PRIORIDAD_UNO[[#This Row],[Nombre del requerimiento]],'Cálculos Manual'!A:J,10,FALSE)), WORKDAY(PRIORIDAD_UNO[[#This Row],[Comienzo Calidad]],IF(PRIORIDAD_UNO[[#This Row],[Tamaño]]="Pequeño",30,IF(PRIORIDAD_UNO[[#This Row],[Tamaño]]="Mediano",40,50)),FERIADOS[Fecha]), VLOOKUP(PRIORIDAD_UNO[[#This Row],[Nombre del requerimiento]],'Cálculos Manual'!A:J,10,FALSE))) -> 46448 | U6: =IF(PRIORIDAD_UNO[[#This Row],[Fin Calidad]]="","",IF(ISBLANK(VLOOKUP(PRIORIDAD_UNO[[#This Row],[Nombre del requerimiento]],'Cálculos Manual'!A:L,12,FALSE)), WORKDAY(PRIORIDAD_UNO[[#This Row],[Fin Calidad]],5,FERIADOS[Fecha]), VLOOKUP(PRIORIDAD_UNO[[#This Row],[Nombre del requerimiento]],'Cálculos Manual'!A:L,12,FALSE))) -> 46455 | V6: =IF(PRIORIDAD_UNO[[#This Row],[Comienzo Producción]]="","",IF(ISBLANK(VLOOKUP(PRIORIDAD_UNO[[#This Row],[Nombre del requerimiento]],'Cálculos Manual'!A:N,14,FALSE)), WORKDAY(PRIORIDAD_UNO[[#This Row],[Comienzo Producción]],IF(PRIORIDAD_UNO[[#This Row],[Tamaño]]="Grande",10,5),FERIADOS[Fecha]), VLOOKUP(PRIORIDAD_UNO[[#This Row],[Nombre del requerimiento]],'Cálculos Manual'!A:N,14,FALSE))) -> 46469 | W6: =IFERROR(PRIORIDAD_UNO[[#This Row],[Fin Producción]]-PRIORIDAD_UNO[[#This Row],[Comienzo Desarrollo]],"") -> 265 | X6: =IF(ISBLANK(PRIORIDAD_UNO[[#This Row],[Comienzo Desarrollo]]),"Sin Fecha","Con Fecha") -> Con Fecha | Y6: =IF(PRIORIDAD_UNO[[#This Row],[Esfuerzo Estimado Desarrollo]]="No definido","Sin esfuerzo","Con esfuerzo") -> Con esfuerzo | Z6: =IF(ISBLANK(PRIORIDAD_UNO[[#This Row],[Comienzo Desarrollo]]),"🔵 Sin Fecha", IF(PRIORIDAD_UNO[[#This Row],[Comienzo Desarrollo]]<TODAY(),"🔴 Vencido", IF(PRIORIDAD_UNO[[#This Row],[Comienzo Desarrollo]]=TODAY(),"🟡 Vence hoy", IF((PRIORIDAD_UNO[[#This Row],[Comienzo Desarrollo]]-TODAY())<=5,"🟠 Por vencer", "🟢 A tiempo")))) -> 🟢 A tiempo | AA6: =IF(PRIORIDAD_UNO[[#This Row],[Comienzo Producción]]="","Por Definir",_xlfn.CONCAT(YEAR(PRIORIDAD_UNO[[#This Row],[Comienzo Producción]])," - ", MONTH(PRIORIDAD_UNO[[#This Row],[Comienzo Producción]]))) -> 2027 - 3 | AB6: 3327
A7: VCX el cual reemplaza al edit package - Mandatorio Visa | B7: 1 | C7: 6 | D7: 3 meses | E7: =IF(OR(ISBLANK(PRIORIDAD_UNO[[#This Row],[Esfuerzo Estimado Desarrollo]]),PRIORIDAD_UNO[[#This Row],[Esfuerzo Estimado Desarrollo]]="No definido"),"No definido", IF(VALUE(TRIM(LEFT(PRIORIDAD_UNO[[#This Row],[Esfuerzo Estimado Desarrollo]],2)))<=1,"Pequeño", IF(VALUE(TRIM(LEFT(PRIORIDAD_UNO[[#This Row],[Esfuerzo Estimado Desarrollo]],2)))<=3,"Mediano", IF(VALUE(TRIM(LEFT(PRIORIDAD_UNO[[#This Row],[Esfuerzo Estimado Desarrollo]],2)))<=5,"Grande", IF(VALUE(TRIM(LEFT(PRIORIDAD_UNO[[#This Row],[Esfuerzo Estimado Desarrollo]],2)))<=7,"Extra Grande","Proyecto"))))) -> Mediano | F7: Banca Digital | G7: Canales Alternos | H7: Canales Virtuales | I7: MEMORANDO N° 00000091 -2026-BN/3252 | J7: Sí | K7: Mandatorio | L7: Pendiente de Atención | M7: Sistemas Bancarios | N7: Vladimir Cajavilca | O7: Omar Sarmiento | Q7: 46113 | R7: =IF(OR(PRIORIDAD_UNO[[#This Row],[Tamaño]]="No definido",ISBLANK(PRIORIDAD_UNO[[#This Row],[Comienzo Desarrollo]])),"",IF(ISBLANK( VLOOKUP(PRIORIDAD_UNO[[#This Row],[Nombre del requerimiento]],'Cálculos Manual'!A:F,6,FALSE)), WORKDAY(PRIORIDAD_UNO[[#This Row],[Comienzo Desarrollo]], IF(PRIORIDAD_UNO[[#This Row],[Tamaño]]="Pequeño",30,IF(PRIORIDAD_UNO[[#This Row],[Tamaño]]="Mediano",66,IF(PRIORIDAD_UNO[[#This Row],[Tamaño]]="Grande",110,IF(PRIORIDAD_UNO[[#This Row],[Tamaño]]="Extra Grande",154,176)))), FERIADOS[Fecha]), VLOOKUP(PRIORIDAD_UNO[[#This Row],[Nombre del requerimiento]],'Cálculos Manual'!A:F,6,FALSE))) -> 46211 | S7: =IF(PRIORIDAD_UNO[[#This Row],[Fin Desarrollo]]="","",IF(ISBLANK(VLOOKUP(PRIORIDAD_UNO[[#This Row],[Nombre del requerimiento]],'Cálculos Manual'!A:H,8,FALSE)),WORKDAY(PRIORIDAD_UNO[[#This Row],[Fin Desarrollo]],5,FERIADOS[Fecha]), VLOOKUP(PRIORIDAD_UNO[[#This Row],[Nombre del requerimiento]],'Cálculos Manual'!A:H,8,FALSE))) -> 46218 | T7: =IF(PRIORIDAD_UNO[[#This Row],[Comienzo Calidad]]="","",IF(ISBLANK(VLOOKUP(PRIORIDAD_UNO[[#This Row],[Nombre del requerimiento]],'Cálculos Manual'!A:J,10,FALSE)), WORKDAY(PRIORIDAD_UNO[[#This Row],[Comienzo Calidad]],IF(PRIORIDAD_UNO[[#This Row],[Tamaño]]="Pequeño",30,IF(PRIORIDAD_UNO[[#This Row],[Tamaño]]="Mediano",40,50)),FERIADOS[Fecha]), VLOOKUP(PRIORIDAD_UNO[[#This Row],[Nombre del requerimiento]],'Cálculos Manual'!A:J,10,FALSE))) -> 46280 | U7: =IF(PRIORIDAD_UNO[[#This Row],[Fin Calidad]]="","",IF(ISBLANK(VLOOKUP(PRIORIDAD_UNO[[#This Row],[Nombre del requerimiento]],'Cálculos Manual'!A:L,12,FALSE)), WORKDAY(PRIORIDAD_UNO[[#This Row],[Fin Calidad]],5,FERIADOS[Fecha]), VLOOKUP(PRIORIDAD_UNO[[#This Row],[Nombre del requerimiento]],'Cálculos Manual'!A:L,12,FALSE))) -> 46287 | V7: =IF(PRIORIDAD_UNO[[#This Row],[Comienzo Producción]]="","",IF(ISBLANK(VLOOKUP(PRIORIDAD_UNO[[#This Row],[Nombre del requerimiento]],'Cálculos Manual'!A:N,14,FALSE)), WORKDAY(PRIORIDAD_UNO[[#This Row],[Comienzo Producción]],IF(PRIORIDAD_UNO[[#This Row],[Tamaño]]="Grande",10,5),FERIADOS[Fecha]), VLOOKUP(PRIORIDAD_UNO[[#This Row],[Nombre del requerimiento]],'Cálculos Manual'!A:N,14,FALSE))) -> 46294 | W7: =IFERROR(PRIORIDAD_UNO[[#This Row],[Fin Producción]]-PRIORIDAD_UNO[[#This Row],[Comienzo Desarrollo]],"") -> 181 | X7: =IF(ISBLANK(PRIORIDAD_UNO[[#This Row],[Comienzo Desarrollo]]),"Sin Fecha","Con Fecha") -> Con Fecha | Y7: =IF(PRIORIDAD_UNO[[#This Row],[Esfuerzo Estimado Desarrollo]]="No definido","Sin esfuerzo","Con esfuerzo") -> Con esfuerzo | Z7: =IF(ISBLANK(PRIORIDAD_UNO[[#This Row],[Comienzo Desarrollo]]),"🔵 Sin Fecha", IF(PRIORIDAD_UNO[[#This Row],[Comienzo Desarrollo]]<TODAY(),"🔴 Vencido", IF(PRIORIDAD_UNO[[#This Row],[Comienzo Desarrollo]]=TODAY(),"🟡 Vence hoy", IF((PRIORIDAD_UNO[[#This Row],[Comienzo Desarrollo]]-TODAY())<=5,"🟠 Por vencer", "🟢 A tiempo")))) -> 🔴 Vencido | AA7: =IF(PRIORIDAD_UNO[[#This Row],[Comienzo Producción]]="","Por Definir",_xlfn.CONCAT(YEAR(PRIORIDAD_UNO[[#This Row],[Comienzo Producción]])," - ", MONTH(PRIORIDAD_UNO[[#This Row],[Comienzo Producción]]))) -> 2026 - 9 | AB7: No está
A8: Transferencias Inmediatas Masivas vía CCE | B8: 1 | C8: 14 | D8: 4 meses | E8: =IF(OR(ISBLANK(PRIORIDAD_UNO[[#This Row],[Esfuerzo Estimado Desarrollo]]),PRIORIDAD_UNO[[#This Row],[Esfuerzo Estimado Desarrollo]]="No definido"),"No definido", IF(VALUE(TRIM(LEFT(PRIORIDAD_UNO[[#This Row],[Esfuerzo Estimado Desarrollo]],2)))<=1,"Pequeño", IF(VALUE(TRIM(LEFT(PRIORIDAD_UNO[[#This Row],[Esfuerzo Estimado Desarrollo]],2)))<=3,"Mediano", IF(VALUE(TRIM(LEFT(PRIORIDAD_UNO[[#This Row],[Esfuerzo Estimado Desarrollo]],2)))<=5,"Grande", IF(VALUE(TRIM(LEFT(PRIORIDAD_UNO[[#This Row],[Esfuerzo Estimado Desarrollo]],2)))<=7,"Extra Grande","Proyecto"))))) -> Grande | F8: Operaciones | G8: SubGerencia de Captaciones y Pagaduria | H8: Sistema de Pagos | I8: MEMORANDO N° 00000166 - 2025-BN/3116 | J8: Sí | K8: Recomendación | L8: Pendiente de Atención | M8: Sistemas Bancarios | N8: Waldo Basurto | O8: Junior Quicaño | P8: Anexo 2 indica que es un requerimiento evolutivo. | Q8: 46251 | R8: =IF(OR(PRIORIDAD_UNO[[#This Row],[Tamaño]]="No definido",ISBLANK(PRIORIDAD_UNO[[#This Row],[Comienzo Desarrollo]])),"",IF(ISBLANK( VLOOKUP(PRIORIDAD_UNO[[#This Row],[Nombre del requerimiento]],'Cálculos Manual'!A:F,6,FALSE)), WORKDAY(PRIORIDAD_UNO[[#This Row],[Comienzo Desarrollo]], IF(PRIORIDAD_UNO[[#This Row],[Tamaño]]="Pequeño",30,IF(PRIORIDAD_UNO[[#This Row],[Tamaño]]="Mediano",66,IF(PRIORIDAD_UNO[[#This Row],[Tamaño]]="Grande",110,IF(PRIORIDAD_UNO[[#This Row],[Tamaño]]="Extra Grande",154,176)))), FERIADOS[Fecha]), VLOOKUP(PRIORIDAD_UNO[[#This Row],[Nombre del requerimiento]],'Cálculos Manual'!A:F,6,FALSE))) -> 46412 | S8: =IF(PRIORIDAD_UNO[[#This Row],[Fin Desarrollo]]="","",IF(ISBLANK(VLOOKUP(PRIORIDAD_UNO[[#This Row],[Nombre del requerimiento]],'Cálculos Manual'!A:H,8,FALSE)),WORKDAY(PRIORIDAD_UNO[[#This Row],[Fin Desarrollo]],5,FERIADOS[Fecha]), VLOOKUP(PRIORIDAD_UNO[[#This Row],[Nombre del requerimiento]],'Cálculos Manual'!A:H,8,FALSE))) -> 46419 | T8: =IF(PRIORIDAD_UNO[[#This Row],[Comienzo Calidad]]="","",IF(ISBLANK(VLOOKUP(PRIORIDAD_UNO[[#This Row],[Nombre del requerimiento]],'Cálculos Manual'!A:J,10,FALSE)), WORKDAY(PRIORIDAD_UNO[[#This Row],[Comienzo Calidad]],IF(PRIORIDAD_UNO[[#This Row],[Tamaño]]="Pequeño",30,IF(PRIORIDAD_UNO[[#This Row],[Tamaño]]="Mediano",40,50)),FERIADOS[Fecha]), VLOOKUP(PRIORIDAD_UNO[[#This Row],[Nombre del requerimiento]],'Cálculos Manual'!A:J,10,FALSE))) -> 46491 | U8: =IF(PRIORIDAD_UNO[[#This Row],[Fin Calidad]]="","",IF(ISBLANK(VLOOKUP(PRIORIDAD_UNO[[#This Row],[Nombre del requerimiento]],'Cálculos Manual'!A:L,12,FALSE)), WORKDAY(PRIORIDAD_UNO[[#This Row],[Fin Calidad]],5,FERIADOS[Fecha]), VLOOKUP(PRIORIDAD_UNO[[#This Row],[Nombre del requerimiento]],'Cálculos Manual'!A:L,12,FALSE))) -> 46498 | V8: =IF(PRIORIDAD_UNO[[#This Row],[Comienzo Producción]]="","",IF(ISBLANK(VLOOKUP(PRIORIDAD_UNO[[#This Row],[Nombre del requerimiento]],'Cálculos Manual'!A:N,14,FALSE)), WORKDAY(PRIORIDAD_UNO[[#This Row],[Comienzo Producción]],IF(PRIORIDAD_UNO[[#This Row],[Tamaño]]="Grande",10,5),FERIADOS[Fecha]), VLOOKUP(PRIORIDAD_UNO[[#This Row],[Nombre del requerimiento]],'Cálculos Manual'!A:N,14,FALSE))) -> 46512 | W8: =IFERROR(PRIORIDAD_UNO[[#This Row],[Fin Producción]]-PRIORIDAD_UNO[[#This Row],[Comienzo Desarrollo]],"") -> 261 | X8: =IF(ISBLANK(PRIORIDAD_UNO[[#This Row],[Comienzo Desarrollo]]),"Sin Fecha","Con Fecha") -> Con Fecha | Y8: =IF(PRIORIDAD_UNO[[#This Row],[Esfuerzo Estimado Desarrollo]]="No definido","Sin esfuerzo","Con esfuerzo") -> Con esfuerzo | Z8: =IF(ISBLANK(PRIORIDAD_UNO[[#This Row],[Comienzo Desarrollo]]),"🔵 Sin Fecha", IF(PRIORIDAD_UNO[[#This Row],[Comienzo Desarrollo]]<TODAY(),"🔴 Vencido", IF(PRIORIDAD_UNO[[#This Row],[Comienzo Desarrollo]]=TODAY(),"🟡 Vence hoy", IF((PRIORIDAD_UNO[[#This Row],[Comienzo Desarrollo]]-TODAY())<=5,"🟠 Por vencer", "🟢 A tiempo")))) -> 🟢 A tiempo | AA8: =IF(PRIORIDAD_UNO[[#This Row],[Comienzo Producción]]="","Por Definir",_xlfn.CONCAT(YEAR(PRIORIDAD_UNO[[#This Row],[Comienzo Producción]])," - ", MONTH(PRIORIDAD_UNO[[#This Row],[Comienzo Producción]]))) -> 2027 - 4 | AB8: 3227
A9: Transferencias a contacto hacia Cuentas BN con consulta en Directorio Interno BN (SIX/STI) | B9: 1 | C9: 37 | D9: No definido | E9: =IF(OR(ISBLANK(PRIORIDAD_UNO[[#This Row],[Esfuerzo Estimado Desarrollo]]),PRIORIDAD_UNO[[#This Row],[Esfuerzo Estimado Desarrollo]]="No definido"),"No definido", IF(VALUE(TRIM(LEFT(PRIORIDAD_UNO[[#This Row],[Esfuerzo Estimado Desarrollo]],2)))<=1,"Pequeño", IF(VALUE(TRIM(LEFT(PRIORIDAD_UNO[[#This Row],[Esfuerzo Estimado Desarrollo]],2)))<=3,"Mediano", IF(VALUE(TRIM(LEFT(PRIORIDAD_UNO[[#This Row],[Esfuerzo Estimado Desarrollo]],2)))<=5,"Grande", IF(VALUE(TRIM(LEFT(PRIORIDAD_UNO[[#This Row],[Esfuerzo Estimado Desarrollo]],2)))<=7,"Extra Grande","Proyecto"))))) -> No definido | F9: Operaciones | G9: SubGerencia de Captaciones y Pagaduria | H9: Sistema de Pagos | I9: MEMORANDO N° 00000022 - 2026-BN/3116 | J9: Sí | K9: Evolutivo | L9: Observado | M9: Soluciones Digitales | N9: Mario Carbajo | O9: Junior Quicaño | P9: El tiempo estimado de implementación debe ser evaluado por el Proveedor Novatronic, coordinar con el área usuaria. Una vez nos confirmen la planificación de atención, estimaremos los plazos de atencion BN. | R9: =IF(OR(PRIORIDAD_UNO[[#This Row],[Tamaño]]="No definido",ISBLANK(PRIORIDAD_UNO[[#This Row],[Comienzo Desarrollo]])),"",IF(ISBLANK( VLOOKUP(PRIORIDAD_UNO[[#This Row],[Nombre del requerimiento]],'Cálculos Manual'!A:F,6,FALSE)), WORKDAY(PRIORIDAD_UNO[[#This Row],[Comienzo Desarrollo]], IF(PRIORIDAD_UNO[[#This Row],[Tamaño]]="Pequeño",30,IF(PRIORIDAD_UNO[[#This Row],[Tamaño]]="Mediano",66,IF(PRIORIDAD_UNO[[#This Row],[Tamaño]]="Grande",110,IF(PRIORIDAD_UNO[[#This Row],[Tamaño]]="Extra Grande",154,176)))), FERIADOS[Fecha]), VLOOKUP(PRIORIDAD_UNO[[#This Row],[Nombre del requerimiento]],'Cálculos Manual'!A:F,6,FALSE))) | S9: =IF(PRIORIDAD_UNO[[#This Row],[Fin Desarrollo]]="","",IF(ISBLANK(VLOOKUP(PRIORIDAD_UNO[[#This Row],[Nombre del requerimiento]],'Cálculos Manual'!A:H,8,FALSE)),WORKDAY(PRIORIDAD_UNO[[#This Row],[Fin Desarrollo]],5,FERIADOS[Fecha]), VLOOKUP(PRIORIDAD_UNO[[#This Row],[Nombre del requerimiento]],'Cálculos Manual'!A:H,8,FALSE))) | T9: =IF(PRIORIDAD_UNO[[#This Row],[Comienzo Calidad]]="","",IF(ISBLANK(VLOOKUP(PRIORIDAD_UNO[[#This Row],[Nombre del requerimiento]],'Cálculos Manual'!A:J,10,FALSE)), WORKDAY(PRIORIDAD_UNO[[#This Row],[Comienzo Calidad]],IF(PRIORIDAD_UNO[[#This Row],[Tamaño]]="Pequeño",30,IF(PRIORIDAD_UNO[[#This Row],[Tamaño]]="Mediano",40,50)),FERIADOS[Fecha]), VLOOKUP(PRIORIDAD_UNO[[#This Row],[Nombre del requerimiento]],'Cálculos Manual'!A:J,10,FALSE))) | U9: =IF(PRIORIDAD_UNO[[#This Row],[Fin Calidad]]="","",IF(ISBLANK(VLOOKUP(PRIORIDAD_UNO[[#This Row],[Nombre del requerimiento]],'Cálculos Manual'!A:L,12,FALSE)), WORKDAY(PRIORIDAD_UNO[[#This Row],[Fin Calidad]],5,FERIADOS[Fecha]), VLOOKUP(PRIORIDAD_UNO[[#This Row],[Nombre del requerimiento]],'Cálculos Manual'!A:L,12,FALSE))) | V9: =IF(PRIORIDAD_UNO[[#This Row],[Comienzo Producción]]="","",IF(ISBLANK(VLOOKUP(PRIORIDAD_UNO[[#This Row],[Nombre del requerimiento]],'Cálculos Manual'!A:N,14,FALSE)), WORKDAY(PRIORIDAD_UNO[[#This Row],[Comienzo Producción]],IF(PRIORIDAD_UNO[[#This Row],[Tamaño]]="Grande",10,5),FERIADOS[Fecha]), VLOOKUP(PRIORIDAD_UNO[[#This Row],[Nombre del requerimiento]],'Cálculos Manual'!A:N,14,FALSE))) | W9: =IFERROR(PRIORIDAD_UNO[[#This Row],[Fin Producción]]-PRIORIDAD_UNO[[#This Row],[Comienzo Desarrollo]],"") | X9: =IF(ISBLANK(PRIORIDAD_UNO[[#This Row],[Comienzo Desarrollo]]),"Sin Fecha","Con Fecha") -> Sin Fecha | Y9: =IF(PRIORIDAD_UNO[[#This Row],[Esfuerzo Estimado Desarrollo]]="No definido","Sin esfuerzo","Con esfuerzo") -> Sin esfuerzo | Z9: =IF(ISBLANK(PRIORIDAD_UNO[[#This Row],[Comienzo Desarrollo]]),"🔵 Sin Fecha", IF(PRIORIDAD_UNO[[#This Row],[Comienzo Desarrollo]]<TODAY(),"🔴 Vencido", IF(PRIORIDAD_UNO[[#This Row],[Comienzo Desarrollo]]=TODAY(),"🟡 Vence hoy", IF((PRIORIDAD_UNO[[#This Row],[Comienzo Desarrollo]]-TODAY())<=5,"🟠 Por vencer", "🟢 A tiempo")))) -> 🔵 Sin Fecha | AA9: =IF(PRIORIDAD_UNO[[#This Row],[Comienzo Producción]]="","Por Definir",_xlfn.CONCAT(YEAR(PRIORIDAD_UNO[[#This Row],[Comienzo Producción]])," - ", MONTH(PRIORIDAD_UNO[[#This Row],[Comienzo Producción]]))) -> Por Definir | AB9: No está
A10: Tasas preferenciales para Tarjeta de Crédito | B10: 1 | C10: 14 | D10: 3 meses | E10: =IF(OR(ISBLANK(PRIORIDAD_UNO[[#This Row],[Esfuerzo Estimado Desarrollo]]),PRIORIDAD_UNO[[#This Row],[Esfuerzo Estimado Desarrollo]]="No definido"),"No definido", IF(VALUE(TRIM(LEFT(PRIORIDAD_UNO[[#This Row],[Esfuerzo Estimado Desarrollo]],2)))<=1,"Pequeño", IF(VALUE(TRIM(LEFT(PRIORIDAD_UNO[[#This Row],[Esfuerzo Estimado Desarrollo]],2)))<=3,"Mediano", IF(VALUE(TRIM(LEFT(PRIORIDAD_UNO[[#This Row],[Esfuerzo Estimado Desarrollo]],2)))<=5,"Grande", IF(VALUE(TRIM(LEFT(PRIORIDAD_UNO[[#This Row],[Esfuerzo Estimado Desarrollo]],2)))<=7,"Extra Grande","Proyecto"))))) -> Mediano | F10: Productos e Inclusión Financiera | G10: Banca Personal | H10: Tarjeta de Crédito | I10: No | J10: Sí | K10: Normativo | L10: Pendiente de Atención | M10: Sistemas Bancarios | N10: Waldo Basurto / Fiorella Galvan | O10: Milagros Huamani | Q10: 46237 | R10: =IF(OR(PRIORIDAD_UNO[[#This Row],[Tamaño]]="No definido",ISBLANK(PRIORIDAD_UNO[[#This Row],[Comienzo Desarrollo]])),"",IF(ISBLANK( VLOOKUP(PRIORIDAD_UNO[[#This Row],[Nombre del requerimiento]],'Cálculos Manual'!A:F,6,FALSE)), WORKDAY(PRIORIDAD_UNO[[#This Row],[Comienzo Desarrollo]], IF(PRIORIDAD_UNO[[#This Row],[Tamaño]]="Pequeño",30,IF(PRIORIDAD_UNO[[#This Row],[Tamaño]]="Mediano",66,IF(PRIORIDAD_UNO[[#This Row],[Tamaño]]="Grande",110,IF(PRIORIDAD_UNO[[#This Row],[Tamaño]]="Extra Grande",154,176)))), FERIADOS[Fecha]), VLOOKUP(PRIORIDAD_UNO[[#This Row],[Nombre del requerimiento]],'Cálculos Manual'!A:F,6,FALSE))) -> 46331 | S10: =IF(PRIORIDAD_UNO[[#This Row],[Fin Desarrollo]]="","",IF(ISBLANK(VLOOKUP(PRIORIDAD_UNO[[#This Row],[Nombre del requerimiento]],'Cálculos Manual'!A:H,8,FALSE)),WORKDAY(PRIORIDAD_UNO[[#This Row],[Fin Desarrollo]],5,FERIADOS[Fecha]), VLOOKUP(PRIORIDAD_UNO[[#This Row],[Nombre del requerimiento]],'Cálculos Manual'!A:H,8,FALSE))) -> 46338 | T10: =IF(PRIORIDAD_UNO[[#This Row],[Comienzo Calidad]]="","",IF(ISBLANK(VLOOKUP(PRIORIDAD_UNO[[#This Row],[Nombre del requerimiento]],'Cálculos Manual'!A:J,10,FALSE)), WORKDAY(PRIORIDAD_UNO[[#This Row],[Comienzo Calidad]],IF(PRIORIDAD_UNO[[#This Row],[Tamaño]]="Pequeño",30,IF(PRIORIDAD_UNO[[#This Row],[Tamaño]]="Mediano",40,50)),FERIADOS[Fecha]), VLOOKUP(PRIORIDAD_UNO[[#This Row],[Nombre del requerimiento]],'Cálculos Manual'!A:J,10,FALSE))) -> 46400 | U10: =IF(PRIORIDAD_UNO[[#This Row],[Fin Calidad]]="","",IF(ISBLANK(VLOOKUP(PRIORIDAD_UNO[[#This Row],[Nombre del requerimiento]],'Cálculos Manual'!A:L,12,FALSE)), WORKDAY(PRIORIDAD_UNO[[#This Row],[Fin Calidad]],5,FERIADOS[Fecha]), VLOOKUP(PRIORIDAD_UNO[[#This Row],[Nombre del requerimiento]],'Cálculos Manual'!A:L,12,FALSE))) -> 46407 | V10: =IF(PRIORIDAD_UNO[[#This Row],[Comienzo Producción]]="","",IF(ISBLANK(VLOOKUP(PRIORIDAD_UNO[[#This Row],[Nombre del requerimiento]],'Cálculos Manual'!A:N,14,FALSE)), WORKDAY(PRIORIDAD_UNO[[#This Row],[Comienzo Producción]],IF(PRIORIDAD_UNO[[#This Row],[Tamaño]]="Grande",10,5),FERIADOS[Fecha]), VLOOKUP(PRIORIDAD_UNO[[#This Row],[Nombre del requerimiento]],'Cálculos Manual'!A:N,14,FALSE))) -> 46414 | W10: =IFERROR(PRIORIDAD_UNO[[#This Row],[Fin Producción]]-PRIORIDAD_UNO[[#This Row],[Comienzo Desarrollo]],"") -> 177 | X10: =IF(ISBLANK(PRIORIDAD_UNO[[#This Row],[Comienzo Desarrollo]]),"Sin Fecha","Con Fecha") -> Con Fecha | Y10: =IF(PRIORIDAD_UNO[[#This Row],[Esfuerzo Estimado Desarrollo]]="No definido","Sin esfuerzo","Con esfuerzo") -> Con esfuerzo | Z10: =IF(ISBLANK(PRIORIDAD_UNO[[#This Row],[Comienzo Desarrollo]]),"🔵 Sin Fecha", IF(PRIORIDAD_UNO[[#This Row],[Comienzo Desarrollo]]<TODAY(),"🔴 Vencido", IF(PRIORIDAD_UNO[[#This Row],[Comienzo Desarrollo]]=TODAY(),"🟡 Vence hoy", IF((PRIORIDAD_UNO[[#This Row],[Comienzo Desarrollo]]-TODAY())<=5,"🟠 Por vencer", "🟢 A tiempo")))) -> 🟢 A tiempo | AA10: =IF(PRIORIDAD_UNO[[#This Row],[Comienzo Producción]]="","Por Definir",_xlfn.CONCAT(YEAR(PRIORIDAD_UNO[[#This Row],[Comienzo Producción]])," - ", MONTH(PRIORIDAD_UNO[[#This Row],[Comienzo Producción]]))) -> 2027 - 1 | AB10: No está
A11: Solución integral a los casos de duplicidad de apertura de cuentas de Ahorro y casos de clientes sin datos y cuentas cruzadas | B11: 1 | C11: 19 | D11: 3 meses | E11: =IF(OR(ISBLANK(PRIORIDAD_UNO[[#This Row],[Esfuerzo Estimado Desarrollo]]),PRIORIDAD_UNO[[#This Row],[Esfuerzo Estimado Desarrollo]]="No definido"),"No definido", IF(VALUE(TRIM(LEFT(PRIORIDAD_UNO[[#This Row],[Esfuerzo Estimado Desarrollo]],2)))<=1,"Pequeño", IF(VALUE(TRIM(LEFT(PRIORIDAD_UNO[[#This Row],[Esfuerzo Estimado Desarrollo]],2)))<=3,"Mediano", IF(VALUE(TRIM(LEFT(PRIORIDAD_UNO[[#This Row],[Esfuerzo Estimado Desarrollo]],2)))<=5,"Grande", IF(VALUE(TRIM(LEFT(PRIORIDAD_UNO[[#This Row],[Esfuerzo Estimado Desarrollo]],2)))<=7,"Extra Grande","Proyecto"))))) -> Mediano | F11: Operaciones | G11: SubGerencia de Captaciones y Pagaduria | H11: Apertura de Cuentas | I11: MEMORANDO N° 00000364 - 2026-BN/3111 (Decía 2025) | J11: Sí | K11: Recomendación | L11: Pendiente de Atención | M11: Sistemas Bancarios | N11: Jhonny Rooca / Norma Fukunaga | O11: Junior Quicaño | P11: Recomendación: Falta sello. | Q11: 46223 | R11: =IF(OR(PRIORIDAD_UNO[[#This Row],[Tamaño]]="No definido",ISBLANK(PRIORIDAD_UNO[[#This Row],[Comienzo Desarrollo]])),"",IF(ISBLANK( VLOOKUP(PRIORIDAD_UNO[[#This Row],[Nombre del requerimiento]],'Cálculos Manual'!A:F,6,FALSE)), WORKDAY(PRIORIDAD_UNO[[#This Row],[Comienzo Desarrollo]], IF(PRIORIDAD_UNO[[#This Row],[Tamaño]]="Pequeño",30,IF(PRIORIDAD_UNO[[#This Row],[Tamaño]]="Mediano",66,IF(PRIORIDAD_UNO[[#This Row],[Tamaño]]="Grande",110,IF(PRIORIDAD_UNO[[#This Row],[Tamaño]]="Extra Grande",154,176)))), FERIADOS[Fecha]), VLOOKUP(PRIORIDAD_UNO[[#This Row],[Nombre del requerimiento]],'Cálculos Manual'!A:F,6,FALSE))) -> 46322 | S11: =IF(PRIORIDAD_UNO[[#This Row],[Fin Desarrollo]]="","",IF(ISBLANK(VLOOKUP(PRIORIDAD_UNO[[#This Row],[Nombre del requerimiento]],'Cálculos Manual'!A:H,8,FALSE)),WORKDAY(PRIORIDAD_UNO[[#This Row],[Fin Desarrollo]],5,FERIADOS[Fecha]), VLOOKUP(PRIORIDAD_UNO[[#This Row],[Nombre del requerimiento]],'Cálculos Manual'!A:H,8,FALSE))) -> 46329 | T11: =IF(PRIORIDAD_UNO[[#This Row],[Comienzo Calidad]]="","",IF(ISBLANK(VLOOKUP(PRIORIDAD_UNO[[#This Row],[Nombre del requerimiento]],'Cálculos Manual'!A:J,10,FALSE)), WORKDAY(PRIORIDAD_UNO[[#This Row],[Comienzo Calidad]],IF(PRIORIDAD_UNO[[#This Row],[Tamaño]]="Pequeño",30,IF(PRIORIDAD_UNO[[#This Row],[Tamaño]]="Mediano",40,50)),FERIADOS[Fecha]), VLOOKUP(PRIORIDAD_UNO[[#This Row],[Nombre del requerimiento]],'Cálculos Manual'!A:J,10,FALSE))) -> 46391 | U11: =IF(PRIORIDAD_UNO[[#This Row],[Fin Calidad]]="","",IF(ISBLANK(VLOOKUP(PRIORIDAD_UNO[[#This Row],[Nombre del requerimiento]],'Cálculos Manual'!A:L,12,FALSE)), WORKDAY(PRIORIDAD_UNO[[#This Row],[Fin Calidad]],5,FERIADOS[Fecha]), VLOOKUP(PRIORIDAD_UNO[[#This Row],[Nombre del requerimiento]],'Cálculos Manual'!A:L,12,FALSE))) -> 46398 | V11: =IF(PRIORIDAD_UNO[[#This Row],[Comienzo Producción]]="","",IF(ISBLANK(VLOOKUP(PRIORIDAD_UNO[[#This Row],[Nombre del requerimiento]],'Cálculos Manual'!A:N,14,FALSE)), WORKDAY(PRIORIDAD_UNO[[#This Row],[Comienzo Producción]],IF(PRIORIDAD_UNO[[#This Row],[Tamaño]]="Grande",10,5),FERIADOS[Fecha]), VLOOKUP(PRIORIDAD_UNO[[#This Row],[Nombre del requerimiento]],'Cálculos Manual'!A:N,14,FALSE))) -> 46405 | W11: =IFERROR(PRIORIDAD_UNO[[#This Row],[Fin Producción]]-PRIORIDAD_UNO[[#This Row],[Comienzo Desarrollo]],"") -> 182 | X11: =IF(ISBLANK(PRIORIDAD_UNO[[#This Row],[Comienzo Desarrollo]]),"Sin Fecha","Con Fecha") -> Con Fecha | Y11: =IF(PRIORIDAD_UNO[[#This Row],[Esfuerzo Estimado Desarrollo]]="No definido","Sin esfuerzo","Con esfuerzo") -> Con esfuerzo | Z11: =IF(ISBLANK(PRIORIDAD_UNO[[#This Row],[Comienzo Desarrollo]]),"🔵 Sin Fecha", IF(PRIORIDAD_UNO[[#This Row],[Comienzo Desarrollo]]<TODAY(),"🔴 Vencido", IF(PRIORIDAD_UNO[[#This Row],[Comienzo Desarrollo]]=TODAY(),"🟡 Vence hoy", IF((PRIORIDAD_UNO[[#This Row],[Comienzo Desarrollo]]-TODAY())<=5,"🟠 Por vencer", "🟢 A tiempo")))) -> 🟢 A tiempo | AA11: =IF(PRIORIDAD_UNO[[#This Row],[Comienzo Producción]]="","Por Definir",_xlfn.CONCAT(YEAR(PRIORIDAD_UNO[[#This Row],[Comienzo Producción]])," - ", MONTH(PRIORIDAD_UNO[[#This Row],[Comienzo Producción]]))) -> 2027 - 1 | AB11: No está
A12: Solicitud de Notificaciones | B12: 1 | C12: 1 | D12: 4 meses | E12: =IF(OR(ISBLANK(PRIORIDAD_UNO[[#This Row],[Esfuerzo Estimado Desarrollo]]),PRIORIDAD_UNO[[#This Row],[Esfuerzo Estimado Desarrollo]]="No definido"),"No definido", IF(VALUE(TRIM(LEFT(PRIORIDAD_UNO[[#This Row],[Esfuerzo Estimado Desarrollo]],2)))<=1,"Pequeño", IF(VALUE(TRIM(LEFT(PRIORIDAD_UNO[[#This Row],[Esfuerzo Estimado Desarrollo]],2)))<=3,"Mediano", IF(VALUE(TRIM(LEFT(PRIORIDAD_UNO[[#This Row],[Esfuerzo Estimado Desarrollo]],2)))<=5,"Grande", IF(VALUE(TRIM(LEFT(PRIORIDAD_UNO[[#This Row],[Esfuerzo Estimado Desarrollo]],2)))<=7,"Extra Grande","Proyecto"))))) -> Grande | F12: Banca Digital | G12: Canales Alternos | H12: Canales Virtuales | I12: MEMORANDO N° 00000518 - 2025-BN/3252 | J12: Sí | K12: Evolutivo | L12: Pendiente de Atención | M12: Soluciones Digitales | N12: Mario Carbajo | O12: Omar Sarmiento | Q12: 46204 | R12: =IF(OR(PRIORIDAD_UNO[[#This Row],[Tamaño]]="No definido",ISBLANK(PRIORIDAD_UNO[[#This Row],[Comienzo Desarrollo]])),"",IF(ISBLANK( VLOOKUP(PRIORIDAD_UNO[[#This Row],[Nombre del requerimiento]],'Cálculos Manual'!A:F,6,FALSE)), WORKDAY(PRIORIDAD_UNO[[#This Row],[Comienzo Desarrollo]], IF(PRIORIDAD_UNO[[#This Row],[Tamaño]]="Pequeño",30,IF(PRIORIDAD_UNO[[#This Row],[Tamaño]]="Mediano",66,IF(PRIORIDAD_UNO[[#This Row],[Tamaño]]="Grande",110,IF(PRIORIDAD_UNO[[#This Row],[Tamaño]]="Extra Grande",154,176)))), FERIADOS[Fecha]), VLOOKUP(PRIORIDAD_UNO[[#This Row],[Nombre del requerimiento]],'Cálculos Manual'!A:F,6,FALSE))) -> 46367 | S12: =IF(PRIORIDAD_UNO[[#This Row],[Fin Desarrollo]]="","",IF(ISBLANK(VLOOKUP(PRIORIDAD_UNO[[#This Row],[Nombre del requerimiento]],'Cálculos Manual'!A:H,8,FALSE)),WORKDAY(PRIORIDAD_UNO[[#This Row],[Fin Desarrollo]],5,FERIADOS[Fecha]), VLOOKUP(PRIORIDAD_UNO[[#This Row],[Nombre del requerimiento]],'Cálculos Manual'!A:H,8,FALSE))) -> 46374 | T12: =IF(PRIORIDAD_UNO[[#This Row],[Comienzo Calidad]]="","",IF(ISBLANK(VLOOKUP(PRIORIDAD_UNO[[#This Row],[Nombre del requerimiento]],'Cálculos Manual'!A:J,10,FALSE)), WORKDAY(PRIORIDAD_UNO[[#This Row],[Comienzo Calidad]],IF(PRIORIDAD_UNO[[#This Row],[Tamaño]]="Pequeño",30,IF(PRIORIDAD_UNO[[#This Row],[Tamaño]]="Mediano",40,50)),FERIADOS[Fecha]), VLOOKUP(PRIORIDAD_UNO[[#This Row],[Nombre del requerimiento]],'Cálculos Manual'!A:J,10,FALSE))) -> 46448 | U12: =IF(PRIORIDAD_UNO[[#This Row],[Fin Calidad]]="","",IF(ISBLANK(VLOOKUP(PRIORIDAD_UNO[[#This Row],[Nombre del requerimiento]],'Cálculos Manual'!A:L,12,FALSE)), WORKDAY(PRIORIDAD_UNO[[#This Row],[Fin Calidad]],5,FERIADOS[Fecha]), VLOOKUP(PRIORIDAD_UNO[[#This Row],[Nombre del requerimiento]],'Cálculos Manual'!A:L,12,FALSE))) -> 46455 | V12: =IF(PRIORIDAD_UNO[[#This Row],[Comienzo Producción]]="","",IF(ISBLANK(VLOOKUP(PRIORIDAD_UNO[[#This Row],[Nombre del requerimiento]],'Cálculos Manual'!A:N,14,FALSE)), WORKDAY(PRIORIDAD_UNO[[#This Row],[Comienzo Producción]],IF(PRIORIDAD_UNO[[#This Row],[Tamaño]]="Grande",10,5),FERIADOS[Fecha]), VLOOKUP(PRIORIDAD_UNO[[#This Row],[Nombre del requerimiento]],'Cálculos Manual'!A:N,14,FALSE))) -> 46469 | W12: =IFERROR(PRIORIDAD_UNO[[#This Row],[Fin Producción]]-PRIORIDAD_UNO[[#This Row],[Comienzo Desarrollo]],"") -> 265 | X12: =IF(ISBLANK(PRIORIDAD_UNO[[#This Row],[Comienzo Desarrollo]]),"Sin Fecha","Con Fecha") -> Con Fecha | Y12: =IF(PRIORIDAD_UNO[[#This Row],[Esfuerzo Estimado Desarrollo]]="No definido","Sin esfuerzo","Con esfuerzo") -> Con esfuerzo | Z12: =IF(ISBLANK(PRIORIDAD_UNO[[#This Row],[Comienzo Desarrollo]]),"🔵 Sin Fecha", IF(PRIORIDAD_UNO[[#This Row],[Comienzo Desarrollo]]<TODAY(),"🔴 Vencido", IF(PRIORIDAD_UNO[[#This Row],[Comienzo Desarrollo]]=TODAY(),"🟡 Vence hoy", IF((PRIORIDAD_UNO[[#This Row],[Comienzo Desarrollo]]-TODAY())<=5,"🟠 Por vencer", "🟢 A tiempo")))) -> 🟢 A tiempo | AA12: =IF(PRIORIDAD_UNO[[#This Row],[Comienzo Producción]]="","Por Definir",_xlfn.CONCAT(YEAR(PRIORIDAD_UNO[[#This Row],[Comienzo Producción]])," - ", MONTH(PRIORIDAD_UNO[[#This Row],[Comienzo Producción]]))) -> 2027 - 3 | AB12: 3141
A13: Solicita implementar cobro de comisión Adquirente Internacional VISA por uso en canal ATM del BN (Consultas y Retiros) | B13: 1 | C13: 9 | D13: 4 Meses | E13: =IF(OR(ISBLANK(PRIORIDAD_UNO[[#This Row],[Esfuerzo Estimado Desarrollo]]),PRIORIDAD_UNO[[#This Row],[Esfuerzo Estimado Desarrollo]]="No definido"),"No definido", IF(VALUE(TRIM(LEFT(PRIORIDAD_UNO[[#This Row],[Esfuerzo Estimado Desarrollo]],2)))<=1,"Pequeño", IF(VALUE(TRIM(LEFT(PRIORIDAD_UNO[[#This Row],[Esfuerzo Estimado Desarrollo]],2)))<=3,"Mediano", IF(VALUE(TRIM(LEFT(PRIORIDAD_UNO[[#This Row],[Esfuerzo Estimado Desarrollo]],2)))<=5,"Grande", IF(VALUE(TRIM(LEFT(PRIORIDAD_UNO[[#This Row],[Esfuerzo Estimado Desarrollo]],2)))<=7,"Extra Grande","Proyecto"))))) -> Grande | F13: Banca Digital | G13: Canales Alternos | H13: Canales Presenciales | I13: MEMORANDO N° 00000044 - 2026-BN/3251 | J13: Sí | K13: Correctivo | L13: Pendiente de Atención | M13: Sistemas Bancarios | N13: Vladimir Cajavilca | O13: Omar Sarmiento | Q13: 46266 | R13: =IF(OR(PRIORIDAD_UNO[[#This Row],[Tamaño]]="No definido",ISBLANK(PRIORIDAD_UNO[[#This Row],[Comienzo Desarrollo]])),"",IF(ISBLANK( VLOOKUP(PRIORIDAD_UNO[[#This Row],[Nombre del requerimiento]],'Cálculos Manual'!A:F,6,FALSE)), WORKDAY(PRIORIDAD_UNO[[#This Row],[Comienzo Desarrollo]], IF(PRIORIDAD_UNO[[#This Row],[Tamaño]]="Pequeño",30,IF(PRIORIDAD_UNO[[#This Row],[Tamaño]]="Mediano",66,IF(PRIORIDAD_UNO[[#This Row],[Tamaño]]="Grande",110,IF(PRIORIDAD_UNO[[#This Row],[Tamaño]]="Extra Grande",154,176)))), FERIADOS[Fecha]), VLOOKUP(PRIORIDAD_UNO[[#This Row],[Nombre del requerimiento]],'Cálculos Manual'!A:F,6,FALSE))) -> 46427 | S13: =IF(PRIORIDAD_UNO[[#This Row],[Fin Desarrollo]]="","",IF(ISBLANK(VLOOKUP(PRIORIDAD_UNO[[#This Row],[Nombre del requerimiento]],'Cálculos Manual'!A:H,8,FALSE)),WORKDAY(PRIORIDAD_UNO[[#This Row],[Fin Desarrollo]],5,FERIADOS[Fecha]), VLOOKUP(PRIORIDAD_UNO[[#This Row],[Nombre del requerimiento]],'Cálculos Manual'!A:H,8,FALSE))) -> 46434 | T13: =IF(PRIORIDAD_UNO[[#This Row],[Comienzo Calidad]]="","",IF(ISBLANK(VLOOKUP(PRIORIDAD_UNO[[#This Row],[Nombre del requerimiento]],'Cálculos Manual'!A:J,10,FALSE)), WORKDAY(PRIORIDAD_UNO[[#This Row],[Comienzo Calidad]],IF(PRIORIDAD_UNO[[#This Row],[Tamaño]]="Pequeño",30,IF(PRIORIDAD_UNO[[#This Row],[Tamaño]]="Mediano",40,50)),FERIADOS[Fecha]), VLOOKUP(PRIORIDAD_UNO[[#This Row],[Nombre del requerimiento]],'Cálculos Manual'!A:J,10,FALSE))) -> 46506 | U13: =IF(PRIORIDAD_UNO[[#This Row],[Fin Calidad]]="","",IF(ISBLANK(VLOOKUP(PRIORIDAD_UNO[[#This Row],[Nombre del requerimiento]],'Cálculos Manual'!A:L,12,FALSE)), WORKDAY(PRIORIDAD_UNO[[#This Row],[Fin Calidad]],5,FERIADOS[Fecha]), VLOOKUP(PRIORIDAD_UNO[[#This Row],[Nombre del requerimiento]],'Cálculos Manual'!A:L,12,FALSE))) -> 46513 | V13: =IF(PRIORIDAD_UNO[[#This Row],[Comienzo Producción]]="","",IF(ISBLANK(VLOOKUP(PRIORIDAD_UNO[[#This Row],[Nombre del requerimiento]],'Cálculos Manual'!A:N,14,FALSE)), WORKDAY(PRIORIDAD_UNO[[#This Row],[Comienzo Producción]],IF(PRIORIDAD_UNO[[#This Row],[Tamaño]]="Grande",10,5),FERIADOS[Fecha]), VLOOKUP(PRIORIDAD_UNO[[#This Row],[Nombre del requerimiento]],'Cálculos Manual'!A:N,14,FALSE))) -> 46527 | W13: =IFERROR(PRIORIDAD_UNO[[#This Row],[Fin Producción]]-PRIORIDAD_UNO[[#This Row],[Comienzo Desarrollo]],"") -> 261 | X13: =IF(ISBLANK(PRIORIDAD_UNO[[#This Row],[Comienzo Desarrollo]]),"Sin Fecha","Con Fecha") -> Con Fecha | Y13: =IF(PRIORIDAD_UNO[[#This Row],[Esfuerzo Estimado Desarrollo]]="No definido","Sin esfuerzo","Con esfuerzo") -> Con esfuerzo | Z13: =IF(ISBLANK(PRIORIDAD_UNO[[#This Row],[Comienzo Desarrollo]]),"🔵 Sin Fecha", IF(PRIORIDAD_UNO[[#This Row],[Comienzo Desarrollo]]<TODAY(),"🔴 Vencido", IF(PRIORIDAD_UNO[[#This Row],[Comienzo Desarrollo]]=TODAY(),"🟡 Vence hoy", IF((PRIORIDAD_UNO[[#This Row],[Comienzo Desarrollo]]-TODAY())<=5,"🟠 Por vencer", "🟢 A tiempo")))) -> 🟢 A tiempo | AA13: =IF(PRIORIDAD_UNO[[#This Row],[Comienzo Producción]]="","Por Definir",_xlfn.CONCAT(YEAR(PRIORIDAD_UNO[[#This Row],[Comienzo Producción]])," - ", MONTH(PRIORIDAD_UNO[[#This Row],[Comienzo Producción]]))) -> 2027 - 5 | AB13: 3200
A14: Sistema Antifraude en el servicio de Transferencias Interbancarias Inmediatas e Interoperabilidad | B14: 1 | C14: 20 | D14: 3 meses | E14: =IF(OR(ISBLANK(PRIORIDAD_UNO[[#This Row],[Esfuerzo Estimado Desarrollo]]),PRIORIDAD_UNO[[#This Row],[Esfuerzo Estimado Desarrollo]]="No definido"),"No definido", IF(VALUE(TRIM(LEFT(PRIORIDAD_UNO[[#This Row],[Esfuerzo Estimado Desarrollo]],2)))<=1,"Pequeño", IF(VALUE(TRIM(LEFT(PRIORIDAD_UNO[[#This Row],[Esfuerzo Estimado Desarrollo]],2)))<=3,"Mediano", IF(VALUE(TRIM(LEFT(PRIORIDAD_UNO[[#This Row],[Esfuerzo Estimado Desarrollo]],2)))<=5,"Grande", IF(VALUE(TRIM(LEFT(PRIORIDAD_UNO[[#This Row],[Esfuerzo Estimado Desarrollo]],2)))<=7,"Extra Grande","Proyecto"))))) -> Mediano | F14: Operaciones | G14: SubGerencia de Captaciones y Pagaduria | H14: Sistema de Pagos | I14: MEMORANDO N° 00000020 - 2026-BN/3116 | J14: Sí | K14: Recomendación | L14: Pendiente de Atención | M14: Soluciones Digitales | N14: Monica Campana | O14: Junior Quicaño | P14: El área usuaria priorizó su atención antes de iniciar el requerimiento de Masivas. Anexo 2 dice evolutivo. | Q14: 46188 | R14: =IF(OR(PRIORIDAD_UNO[[#This Row],[Tamaño]]="No definido",ISBLANK(PRIORIDAD_UNO[[#This Row],[Comienzo Desarrollo]])),"",IF(ISBLANK( VLOOKUP(PRIORIDAD_UNO[[#This Row],[Nombre del requerimiento]],'Cálculos Manual'!A:F,6,FALSE)), WORKDAY(PRIORIDAD_UNO[[#This Row],[Comienzo Desarrollo]], IF(PRIORIDAD_UNO[[#This Row],[Tamaño]]="Pequeño",30,IF(PRIORIDAD_UNO[[#This Row],[Tamaño]]="Mediano",66,IF(PRIORIDAD_UNO[[#This Row],[Tamaño]]="Grande",110,IF(PRIORIDAD_UNO[[#This Row],[Tamaño]]="Extra Grande",154,176)))), FERIADOS[Fecha]), VLOOKUP(PRIORIDAD_UNO[[#This Row],[Nombre del requerimiento]],'Cálculos Manual'!A:F,6,FALSE))) -> 46287 | S14: =IF(PRIORIDAD_UNO[[#This Row],[Fin Desarrollo]]="","",IF(ISBLANK(VLOOKUP(PRIORIDAD_UNO[[#This Row],[Nombre del requerimiento]],'Cálculos Manual'!A:H,8,FALSE)),WORKDAY(PRIORIDAD_UNO[[#This Row],[Fin Desarrollo]],5,FERIADOS[Fecha]), VLOOKUP(PRIORIDAD_UNO[[#This Row],[Nombre del requerimiento]],'Cálculos Manual'!A:H,8,FALSE))) -> 46294 | T14: =IF(PRIORIDAD_UNO[[#This Row],[Comienzo Calidad]]="","",IF(ISBLANK(VLOOKUP(PRIORIDAD_UNO[[#This Row],[Nombre del requerimiento]],'Cálculos Manual'!A:J,10,FALSE)), WORKDAY(PRIORIDAD_UNO[[#This Row],[Comienzo Calidad]],IF(PRIORIDAD_UNO[[#This Row],[Tamaño]]="Pequeño",30,IF(PRIORIDAD_UNO[[#This Row],[Tamaño]]="Mediano",40,50)),FERIADOS[Fecha]), VLOOKUP(PRIORIDAD_UNO[[#This Row],[Nombre del requerimiento]],'Cálculos Manual'!A:J,10,FALSE))) -> 46351 | U14: =IF(PRIORIDAD_UNO[[#This Row],[Fin Calidad]]="","",IF(ISBLANK(VLOOKUP(PRIORIDAD_UNO[[#This Row],[Nombre del requerimiento]],'Cálculos Manual'!A:L,12,FALSE)), WORKDAY(PRIORIDAD_UNO[[#This Row],[Fin Calidad]],5,FERIADOS[Fecha]), VLOOKUP(PRIORIDAD_UNO[[#This Row],[Nombre del requerimiento]],'Cálculos Manual'!A:L,12,FALSE))) -> 46358 | V14: =IF(PRIORIDAD_UNO[[#This Row],[Comienzo Producción]]="","",IF(ISBLANK(VLOOKUP(PRIORIDAD_UNO[[#This Row],[Nombre del requerimiento]],'Cálculos Manual'!A:N,14,FALSE)), WORKDAY(PRIORIDAD_UNO[[#This Row],[Comienzo Producción]],IF(PRIORIDAD_UNO[[#This Row],[Tamaño]]="Grande",10,5),FERIADOS[Fecha]), VLOOKUP(PRIORIDAD_UNO[[#This Row],[Nombre del requerimiento]],'Cálculos Manual'!A:N,14,FALSE))) -> 46367 | W14: =IFERROR(PRIORIDAD_UNO[[#This Row],[Fin Producción]]-PRIORIDAD_UNO[[#This Row],[Comienzo Desarrollo]],"") -> 179 | X14: =IF(ISBLANK(PRIORIDAD_UNO[[#This Row],[Comienzo Desarrollo]]),"Sin Fecha","Con Fecha") -> Con Fecha | Y14: =IF(PRIORIDAD_UNO[[#This Row],[Esfuerzo Estimado Desarrollo]]="No definido","Sin esfuerzo","Con esfuerzo") -> Con esfuerzo | Z14: =IF(ISBLANK(PRIORIDAD_UNO[[#This Row],[Comienzo Desarrollo]]),"🔵 Sin Fecha", IF(PRIORIDAD_UNO[[#This Row],[Comienzo Desarrollo]]<TODAY(),"🔴 Vencido", IF(PRIORIDAD_UNO[[#This Row],[Comienzo Desarrollo]]=TODAY(),"🟡 Vence hoy", IF((PRIORIDAD_UNO[[#This Row],[Comienzo Desarrollo]]-TODAY())<=5,"🟠 Por vencer", "🟢 A tiempo")))) -> 🟠 Por vencer | AA14: =IF(PRIORIDAD_UNO[[#This Row],[Comienzo Producción]]="","Por Definir",_xlfn.CONCAT(YEAR(PRIORIDAD_UNO[[#This Row],[Comienzo Producción]])," - ", MONTH(PRIORIDAD_UNO[[#This Row],[Comienzo Producción]]))) -> 2026 - 12 | AB14: No está
A15: SIRE Registro de Libro Diario | B15: 1 | C15: 3 | D15: 1 mes | E15: =IF(OR(ISBLANK(PRIORIDAD_UNO[[#This Row],[Esfuerzo Estimado Desarrollo]]),PRIORIDAD_UNO[[#This Row],[Esfuerzo Estimado Desarrollo]]="No definido"),"No definido", IF(VALUE(TRIM(LEFT(PRIORIDAD_UNO[[#This Row],[Esfuerzo Estimado Desarrollo]],2)))<=1,"Pequeño", IF(VALUE(TRIM(LEFT(PRIORIDAD_UNO[[#This Row],[Esfuerzo Estimado Desarrollo]],2)))<=3,"Mediano", IF(VALUE(TRIM(LEFT(PRIORIDAD_UNO[[#This Row],[Esfuerzo Estimado Desarrollo]],2)))<=5,"Grande", IF(VALUE(TRIM(LEFT(PRIORIDAD_UNO[[#This Row],[Esfuerzo Estimado Desarrollo]],2)))<=7,"Extra Grande","Proyecto"))))) -> Pequeño | F15: Finanzas y Tesorería | G15: Contabilidad | H15: Centralización y Procesamiento Contable | I15: MEMORANDO N° 00000006 - 2026-BN6215 | J15: Sí | K15: Normativo | L15: Pendiente de Atención | M15: Sistemas Administrativos | N15: Emerson Quecara | O15: Juan Carlos Zavaleta | P15: Equipo técnico en elaboración de crnograma | Q15: 46183 | R15: =IF(OR(PRIORIDAD_UNO[[#This Row],[Tamaño]]="No definido",ISBLANK(PRIORIDAD_UNO[[#This Row],[Comienzo Desarrollo]])),"",IF(ISBLANK( VLOOKUP(PRIORIDAD_UNO[[#This Row],[Nombre del requerimiento]],'Cálculos Manual'!A:F,6,FALSE)), WORKDAY(PRIORIDAD_UNO[[#This Row],[Comienzo Desarrollo]], IF(PRIORIDAD_UNO[[#This Row],[Tamaño]]="Pequeño",30,IF(PRIORIDAD_UNO[[#This Row],[Tamaño]]="Mediano",66,IF(PRIORIDAD_UNO[[#This Row],[Tamaño]]="Grande",110,IF(PRIORIDAD_UNO[[#This Row],[Tamaño]]="Extra Grande",154,176)))), FERIADOS[Fecha]), VLOOKUP(PRIORIDAD_UNO[[#This Row],[Nombre del requerimiento]],'Cálculos Manual'!A:F,6,FALSE))) -> 46227 | S15: =IF(PRIORIDAD_UNO[[#This Row],[Fin Desarrollo]]="","",IF(ISBLANK(VLOOKUP(PRIORIDAD_UNO[[#This Row],[Nombre del requerimiento]],'Cálculos Manual'!A:H,8,FALSE)),WORKDAY(PRIORIDAD_UNO[[#This Row],[Fin Desarrollo]],5,FERIADOS[Fecha]), VLOOKUP(PRIORIDAD_UNO[[#This Row],[Nombre del requerimiento]],'Cálculos Manual'!A:H,8,FALSE))) -> 46238 | T15: =IF(PRIORIDAD_UNO[[#This Row],[Comienzo Calidad]]="","",IF(ISBLANK(VLOOKUP(PRIORIDAD_UNO[[#This Row],[Nombre del requerimiento]],'Cálculos Manual'!A:J,10,FALSE)), WORKDAY(PRIORIDAD_UNO[[#This Row],[Comienzo Calidad]],IF(PRIORIDAD_UNO[[#This Row],[Tamaño]]="Pequeño",30,IF(PRIORIDAD_UNO[[#This Row],[Tamaño]]="Mediano",40,50)),FERIADOS[Fecha]), VLOOKUP(PRIORIDAD_UNO[[#This Row],[Nombre del requerimiento]],'Cálculos Manual'!A:J,10,FALSE))) -> 46281 | U15: =IF(PRIORIDAD_UNO[[#This Row],[Fin Calidad]]="","",IF(ISBLANK(VLOOKUP(PRIORIDAD_UNO[[#This Row],[Nombre del requerimiento]],'Cálculos Manual'!A:L,12,FALSE)), WORKDAY(PRIORIDAD_UNO[[#This Row],[Fin Calidad]],5,FERIADOS[Fecha]), VLOOKUP(PRIORIDAD_UNO[[#This Row],[Nombre del requerimiento]],'Cálculos Manual'!A:L,12,FALSE))) -> 46288 | V15: =IF(PRIORIDAD_UNO[[#This Row],[Comienzo Producción]]="","",IF(ISBLANK(VLOOKUP(PRIORIDAD_UNO[[#This Row],[Nombre del requerimiento]],'Cálculos Manual'!A:N,14,FALSE)), WORKDAY(PRIORIDAD_UNO[[#This Row],[Comienzo Producción]],IF(PRIORIDAD_UNO[[#This Row],[Tamaño]]="Grande",10,5),FERIADOS[Fecha]), VLOOKUP(PRIORIDAD_UNO[[#This Row],[Nombre del requerimiento]],'Cálculos Manual'!A:N,14,FALSE))) -> 46295 | W15: =IFERROR(PRIORIDAD_UNO[[#This Row],[Fin Producción]]-PRIORIDAD_UNO[[#This Row],[Comienzo Desarrollo]],"") -> 112 | X15: =IF(ISBLANK(PRIORIDAD_UNO[[#This Row],[Comienzo Desarrollo]]),"Sin Fecha","Con Fecha") -> Con Fecha | Y15: =IF(PRIORIDAD_UNO[[#This Row],[Esfuerzo Estimado Desarrollo]]="No definido","Sin esfuerzo","Con esfuerzo") -> Con esfuerzo | Z15: =IF(ISBLANK(PRIORIDAD_UNO[[#This Row],[Comienzo Desarrollo]]),"🔵 Sin Fecha", IF(PRIORIDAD_UNO[[#This Row],[Comienzo Desarrollo]]<TODAY(),"🔴 Vencido", IF(PRIORIDAD_UNO[[#This Row],[Comienzo Desarrollo]]=TODAY(),"🟡 Vence hoy", IF((PRIORIDAD_UNO[[#This Row],[Comienzo Desarrollo]]-TODAY())<=5,"🟠 Por vencer", "🟢 A tiempo")))) -> 🔴 Vencido | AA15: =IF(PRIORIDAD_UNO[[#This Row],[Comienzo Producción]]="","Por Definir",_xlfn.CONCAT(YEAR(PRIORIDAD_UNO[[#This Row],[Comienzo Producción]])," - ", MONTH(PRIORIDAD_UNO[[#This Row],[Comienzo Producción]]))) -> 2026 - 9 | AB15: 3265
A16: Separación funcional operativa contable de las remesas ATMs BN e islas Lima entre las Secciones Caja y Canales Presenciales. | B16: 1 | C16: 43 | D16: 7 meses | E16: =IF(OR(ISBLANK(PRIORIDAD_UNO[[#This Row],[Esfuerzo Estimado Desarrollo]]),PRIORIDAD_UNO[[#This Row],[Esfuerzo Estimado Desarrollo]]="No definido"),"No definido", IF(VALUE(TRIM(LEFT(PRIORIDAD_UNO[[#This Row],[Esfuerzo Estimado Desarrollo]],2)))<=1,"Pequeño", IF(VALUE(TRIM(LEFT(PRIORIDAD_UNO[[#This Row],[Esfuerzo Estimado Desarrollo]],2)))<=3,"Mediano", IF(VALUE(TRIM(LEFT(PRIORIDAD_UNO[[#This Row],[Esfuerzo Estimado Desarrollo]],2)))<=5,"Grande", IF(VALUE(TRIM(LEFT(PRIORIDAD_UNO[[#This Row],[Esfuerzo Estimado Desarrollo]],2)))<=7,"Extra Grande","Proyecto"))))) -> Extra Grande | F16: Operaciones | G16: Subgerencia Caja y Valores | H16: Caja y Valores en Custodia | I16: MEMORANDO N° 00000034 - 2026-BN/3131 | J16: Sí | K16: Evolutivo | L16: Pendiente de Atención | M16: Sistemas Administrativos | N16: Ricardo Cuba | O16: Junior Quicaño | Q16: 46300 | R16: =IF(OR(PRIORIDAD_UNO[[#This Row],[Tamaño]]="No definido",ISBLANK(PRIORIDAD_UNO[[#This Row],[Comienzo Desarrollo]])),"",IF(ISBLANK( VLOOKUP(PRIORIDAD_UNO[[#This Row],[Nombre del requerimiento]],'Cálculos Manual'!A:F,6,FALSE)), WORKDAY(PRIORIDAD_UNO[[#This Row],[Comienzo Desarrollo]], IF(PRIORIDAD_UNO[[#This Row],[Tamaño]]="Pequeño",30,IF(PRIORIDAD_UNO[[#This Row],[Tamaño]]="Mediano",66,IF(PRIORIDAD_UNO[[#This Row],[Tamaño]]="Grande",110,IF(PRIORIDAD_UNO[[#This Row],[Tamaño]]="Extra Grande",154,176)))), FERIADOS[Fecha]), VLOOKUP(PRIORIDAD_UNO[[#This Row],[Nombre del requerimiento]],'Cálculos Manual'!A:F,6,FALSE))) -> 46525 | S16: =IF(PRIORIDAD_UNO[[#This Row],[Fin Desarrollo]]="","",IF(ISBLANK(VLOOKUP(PRIORIDAD_UNO[[#This Row],[Nombre del requerimiento]],'Cálculos Manual'!A:H,8,FALSE)),WORKDAY(PRIORIDAD_UNO[[#This Row],[Fin Desarrollo]],5,FERIADOS[Fecha]), VLOOKUP(PRIORIDAD_UNO[[#This Row],[Nombre del requerimiento]],'Cálculos Manual'!A:H,8,FALSE))) -> 46532 | T16: =IF(PRIORIDAD_UNO[[#This Row],[Comienzo Calidad]]="","",IF(ISBLANK(VLOOKUP(PRIORIDAD_UNO[[#This Row],[Nombre del requerimiento]],'Cálculos Manual'!A:J,10,FALSE)), WORKDAY(PRIORIDAD_UNO[[#This Row],[Comienzo Calidad]],IF(PRIORIDAD_UNO[[#This Row],[Tamaño]]="Pequeño",30,IF(PRIORIDAD_UNO[[#This Row],[Tamaño]]="Mediano",40,50)),FERIADOS[Fecha]), VLOOKUP(PRIORIDAD_UNO[[#This Row],[Nombre del requerimiento]],'Cálculos Manual'!A:J,10,FALSE))) -> 46610 | U16: =IF(PRIORIDAD_UNO[[#This Row],[Fin Calidad]]="","",IF(ISBLANK(VLOOKUP(PRIORIDAD_UNO[[#This Row],[Nombre del requerimiento]],'Cálculos Manual'!A:L,12,FALSE)), WORKDAY(PRIORIDAD_UNO[[#This Row],[Fin Calidad]],5,FERIADOS[Fecha]), VLOOKUP(PRIORIDAD_UNO[[#This Row],[Nombre del requerimiento]],'Cálculos Manual'!A:L,12,FALSE))) -> 46617 | V16: =IF(PRIORIDAD_UNO[[#This Row],[Comienzo Producción]]="","",IF(ISBLANK(VLOOKUP(PRIORIDAD_UNO[[#This Row],[Nombre del requerimiento]],'Cálculos Manual'!A:N,14,FALSE)), WORKDAY(PRIORIDAD_UNO[[#This Row],[Comienzo Producción]],IF(PRIORIDAD_UNO[[#This Row],[Tamaño]]="Grande",10,5),FERIADOS[Fecha]), VLOOKUP(PRIORIDAD_UNO[[#This Row],[Nombre del requerimiento]],'Cálculos Manual'!A:N,14,FALSE))) -> 46624 | W16: =IFERROR(PRIORIDAD_UNO[[#This Row],[Fin Producción]]-PRIORIDAD_UNO[[#This Row],[Comienzo Desarrollo]],"") -> 324 | X16: =IF(ISBLANK(PRIORIDAD_UNO[[#This Row],[Comienzo Desarrollo]]),"Sin Fecha","Con Fecha") -> Con Fecha | Y16: =IF(PRIORIDAD_UNO[[#This Row],[Esfuerzo Estimado Desarrollo]]="No definido","Sin esfuerzo","Con esfuerzo") -> Con esfuerzo | Z16: =IF(ISBLANK(PRIORIDAD_UNO[[#This Row],[Comienzo Desarrollo]]),"🔵 Sin Fecha", IF(PRIORIDAD_UNO[[#This Row],[Comienzo Desarrollo]]<TODAY(),"🔴 Vencido", IF(PRIORIDAD_UNO[[#This Row],[Comienzo Desarrollo]]=TODAY(),"🟡 Vence hoy", IF((PRIORIDAD_UNO[[#This Row],[Comienzo Desarrollo]]-TODAY())<=5,"🟠 Por vencer", "🟢 A tiempo")))) -> 🟢 A tiempo | AA16: =IF(PRIORIDAD_UNO[[#This Row],[Comienzo Producción]]="","Por Definir",_xlfn.CONCAT(YEAR(PRIORIDAD_UNO[[#This Row],[Comienzo Producción]])," - ", MONTH(PRIORIDAD_UNO[[#This Row],[Comienzo Producción]]))) -> 2027 - 8 | AB16: 3247
A17: Rporte mensual de saldos de prestamos Multired conforme a los lineamientos del 16c Ratio de Financiación Neta estable | B17: 1 | C17: 6 | D17: 2 meses | E17: =IF(OR(ISBLANK(PRIORIDAD_UNO[[#This Row],[Esfuerzo Estimado Desarrollo]]),PRIORIDAD_UNO[[#This Row],[Esfuerzo Estimado Desarrollo]]="No definido"),"No definido", IF(VALUE(TRIM(LEFT(PRIORIDAD_UNO[[#This Row],[Esfuerzo Estimado Desarrollo]],2)))<=1,"Pequeño", IF(VALUE(TRIM(LEFT(PRIORIDAD_UNO[[#This Row],[Esfuerzo Estimado Desarrollo]],2)))<=3,"Mediano", IF(VALUE(TRIM(LEFT(PRIORIDAD_UNO[[#This Row],[Esfuerzo Estimado Desarrollo]],2)))<=5,"Grande", IF(VALUE(TRIM(LEFT(PRIORIDAD_UNO[[#This Row],[Esfuerzo Estimado Desarrollo]],2)))<=7,"Extra Grande","Proyecto"))))) -> Mediano | F17: Riesgos | G17: Riesgos Crediticios y Financieros | H17: Riesgos Financieros | I17: MEMORANDO N° 00000024 - 2026-BN/2193 | J17: Sí | K17: Normativo | L17: Pendiente de Atención | M17: Sistemas Bancarios | N17: Fiorella Galván | O17: María Barboza | Q17: 46237 | R17: =IF(OR(PRIORIDAD_UNO[[#This Row],[Tamaño]]="No definido",ISBLANK(PRIORIDAD_UNO[[#This Row],[Comienzo Desarrollo]])),"",IF(ISBLANK( VLOOKUP(PRIORIDAD_UNO[[#This Row],[Nombre del requerimiento]],'Cálculos Manual'!A:F,6,FALSE)), WORKDAY(PRIORIDAD_UNO[[#This Row],[Comienzo Desarrollo]], IF(PRIORIDAD_UNO[[#This Row],[Tamaño]]="Pequeño",30,IF(PRIORIDAD_UNO[[#This Row],[Tamaño]]="Mediano",66,IF(PRIORIDAD_UNO[[#This Row],[Tamaño]]="Grande",110,IF(PRIORIDAD_UNO[[#This Row],[Tamaño]]="Extra Grande",154,176)))), FERIADOS[Fecha]), VLOOKUP(PRIORIDAD_UNO[[#This Row],[Nombre del requerimiento]],'Cálculos Manual'!A:F,6,FALSE))) -> 46331 | S17: =IF(PRIORIDAD_UNO[[#This Row],[Fin Desarrollo]]="","",IF(ISBLANK(VLOOKUP(PRIORIDAD_UNO[[#This Row],[Nombre del requerimiento]],'Cálculos Manual'!A:H,8,FALSE)),WORKDAY(PRIORIDAD_UNO[[#This Row],[Fin Desarrollo]],5,FERIADOS[Fecha]), VLOOKUP(PRIORIDAD_UNO[[#This Row],[Nombre del requerimiento]],'Cálculos Manual'!A:H,8,FALSE))) -> 46338 | T17: =IF(PRIORIDAD_UNO[[#This Row],[Comienzo Calidad]]="","",IF(ISBLANK(VLOOKUP(PRIORIDAD_UNO[[#This Row],[Nombre del requerimiento]],'Cálculos Manual'!A:J,10,FALSE)), WORKDAY(PRIORIDAD_UNO[[#This Row],[Comienzo Calidad]],IF(PRIORIDAD_UNO[[#This Row],[Tamaño]]="Pequeño",30,IF(PRIORIDAD_UNO[[#This Row],[Tamaño]]="Mediano",40,50)),FERIADOS[Fecha]), VLOOKUP(PRIORIDAD_UNO[[#This Row],[Nombre del requerimiento]],'Cálculos Manual'!A:J,10,FALSE))) -> 46400 | U17: =IF(PRIORIDAD_UNO[[#This Row],[Fin Calidad]]="","",IF(ISBLANK(VLOOKUP(PRIORIDAD_UNO[[#This Row],[Nombre del requerimiento]],'Cálculos Manual'!A:L,12,FALSE)), WORKDAY(PRIORIDAD_UNO[[#This Row],[Fin Calidad]],5,FERIADOS[Fecha]), VLOOKUP(PRIORIDAD_UNO[[#This Row],[Nombre del requerimiento]],'Cálculos Manual'!A:L,12,FALSE))) -> 46407 | V17: =IF(PRIORIDAD_UNO[[#This Row],[Comienzo Producción]]="","",IF(ISBLANK(VLOOKUP(PRIORIDAD_UNO[[#This Row],[Nombre del requerimiento]],'Cálculos Manual'!A:N,14,FALSE)), WORKDAY(PRIORIDAD_UNO[[#This Row],[Comienzo Producción]],IF(PRIORIDAD_UNO[[#This Row],[Tamaño]]="Grande",10,5),FERIADOS[Fecha]), VLOOKUP(PRIORIDAD_UNO[[#This Row],[Nombre del requerimiento]],'Cálculos Manual'!A:N,14,FALSE))) -> 46414 | W17: =IFERROR(PRIORIDAD_UNO[[#This Row],[Fin Producción]]-PRIORIDAD_UNO[[#This Row],[Comienzo Desarrollo]],"") -> 177 | X17: =IF(ISBLANK(PRIORIDAD_UNO[[#This Row],[Comienzo Desarrollo]]),"Sin Fecha","Con Fecha") -> Con Fecha | Y17: =IF(PRIORIDAD_UNO[[#This Row],[Esfuerzo Estimado Desarrollo]]="No definido","Sin esfuerzo","Con esfuerzo") -> Con esfuerzo | Z17: =IF(ISBLANK(PRIORIDAD_UNO[[#This Row],[Comienzo Desarrollo]]),"🔵 Sin Fecha", IF(PRIORIDAD_UNO[[#This Row],[Comienzo Desarrollo]]<TODAY(),"🔴 Vencido", IF(PRIORIDAD_UNO[[#This Row],[Comienzo Desarrollo]]=TODAY(),"🟡 Vence hoy", IF((PRIORIDAD_UNO[[#This Row],[Comienzo Desarrollo]]-TODAY())<=5,"🟠 Por vencer", "🟢 A tiempo")))) -> 🟢 A tiempo | AA17: =IF(PRIORIDAD_UNO[[#This Row],[Comienzo Producción]]="","Por Definir",_xlfn.CONCAT(YEAR(PRIORIDAD_UNO[[#This Row],[Comienzo Producción]])," - ", MONTH(PRIORIDAD_UNO[[#This Row],[Comienzo Producción]]))) -> 2027 - 1 | AB17: No está
